Traceback (most recent call last):
  File "/home/runner/work/GenomicRanges/GenomicRanges/.tox/docs/lib/python3.11/site-packages/jupyter_cache/executors/utils.py", line 58, in single_nb_execution
    executenb(
  File "/home/runner/work/GenomicRanges/GenomicRanges/.tox/docs/lib/python3.11/site-packages/nbclient/client.py", line 1319, in execute
    return NotebookClient(nb=nb, resources=resources, km=km, **kwargs).execute()
           ^^^^^^^^^^^^^^^^^^^^^^^^^^^^^^^^^^^^^^^^^^^^^^^^^^^^^^^^^^^^^^^^^^^^^
  File "/home/runner/work/GenomicRanges/GenomicRanges/.tox/docs/lib/python3.11/site-packages/jupyter_core/utils/__init__.py", line 165, in wrapped
    return loop.run_until_complete(inner)
           ^^^^^^^^^^^^^^^^^^^^^^^^^^^^^^
  File "/opt/hostedtoolcache/Python/3.11.11/x64/lib/python3.11/asyncio/base_events.py", line 654, in run_until_complete
    return future.result()
           ^^^^^^^^^^^^^^^
  File "/home/runner/work/GenomicRanges/GenomicRanges/.tox/docs/lib/python3.11/site-packages/nbclient/client.py", line 709, in async_execute
    await self.async_execute_cell(
  File "/home/runner/work/GenomicRanges/GenomicRanges/.tox/docs/lib/python3.11/site-packages/nbclient/client.py", line 1062, in async_execute_cell
    await self._check_raise_for_error(cell, cell_index, exec_reply)
  File "/home/runner/work/GenomicRanges/GenomicRanges/.tox/docs/lib/python3.11/site-packages/nbclient/client.py", line 918, in _check_raise_for_error
    raise CellExecutionError.from_cell_and_msg(cell, exec_reply_content)
nbclient.exceptions.CellExecutionError: An error occurred while executing the following cell:
------------------
seqlengths = {"chr1": 100, "chr2": 75, "chr3": 200}

tiles = GenomicRanges.tile_genome(seqlengths=seqlengths, n=10)
print(tiles)
------------------


[0;31m---------------------------------------------------------------------------[0m
[0;31mTypeError[0m                                 Traceback (most recent call last)
Cell [0;32mIn[19], line 3[0m
[1;32m      1[0m seqlengths [38;5;241m=[39m {[38;5;124m"[39m[38;5;124mchr1[39m[38;5;124m"[39m: [38;5;241m100[39m, [38;5;124m"[39m[38;5;124mchr2[39m[38;5;124m"[39m: [38;5;241m75[39m, [38;5;124m"[39m[38;5;124mchr3[39m[38;5;124m"[39m: [38;5;241m200[39m}
[0;32m----> 3[0m tiles [38;5;241m=[39m [43mGenomicRanges[49m[38;5;241;43m.[39;49m[43mtile_genome[49m[43m([49m[43mseqlengths[49m[38;5;241;43m=[39;49m[43mseqlengths[49m[43m,[49m[43m [49m[43mn[49m[38;5;241;43m=[39;49m[38;5;241;43m10[39;49m[43m)[49m
[1;32m      4[0m [38;5;28mprint[39m(tiles)

[0;31mTypeError[0m: GenomicRanges.tile_genome() got an unexpected keyword argument 'n'

