Traceback (most recent call last):
  File "/home/runner/work/GenomicRanges/GenomicRanges/.tox/docs/lib/python3.12/site-packages/jupyter_core/utils/__init__.py", line 154, in wrapped
    asyncio.get_running_loop()
RuntimeError: no running event loop

During handling of the above exception, another exception occurred:

Traceback (most recent call last):
  File "/home/runner/work/GenomicRanges/GenomicRanges/.tox/docs/lib/python3.12/site-packages/jupyter_cache/executors/utils.py", line 58, in single_nb_execution
    executenb(
  File "/home/runner/work/GenomicRanges/GenomicRanges/.tox/docs/lib/python3.12/site-packages/nbclient/client.py", line 1319, in execute
    return NotebookClient(nb=nb, resources=resources, km=km, **kwargs).execute()
           ^^^^^^^^^^^^^^^^^^^^^^^^^^^^^^^^^^^^^^^^^^^^^^^^^^^^^^^^^^^^^^^^^^^^^
  File "/home/runner/work/GenomicRanges/GenomicRanges/.tox/docs/lib/python3.12/site-packages/jupyter_core/utils/__init__.py", line 158, in wrapped
    return loop.run_until_complete(inner)
           ^^^^^^^^^^^^^^^^^^^^^^^^^^^^^^
  File "/opt/hostedtoolcache/Python/3.12.11/x64/lib/python3.12/asyncio/base_events.py", line 691, in run_until_complete
    return future.result()
           ^^^^^^^^^^^^^^^
  File "/home/runner/work/GenomicRanges/GenomicRanges/.tox/docs/lib/python3.12/site-packages/nbclient/client.py", line 709, in async_execute
    await self.async_execute_cell(
  File "/home/runner/work/GenomicRanges/GenomicRanges/.tox/docs/lib/python3.12/site-packages/nbclient/client.py", line 1062, in async_execute_cell
    await self._check_raise_for_error(cell, cell_index, exec_reply)
  File "/home/runner/work/GenomicRanges/GenomicRanges/.tox/docs/lib/python3.12/site-packages/nbclient/client.py", line 918, in _check_raise_for_error
    raise CellExecutionError.from_cell_and_msg(cell, exec_reply_content)
nbclient.exceptions.CellExecutionError: An error occurred while executing the following cell:
------------------
seqlengths = {"chr1": 100, "chr2": 75, "chr3": 200}

tiles = GenomicRanges.tile_genome(seqlengths=seqlengths, n=10)
print(tiles)
------------------


[31m---------------------------------------------------------------------------[39m
[31mTypeError[39m                                 Traceback (most recent call last)
[36mCell[39m[36m [39m[32mIn[19][39m[32m, line 3[39m
[32m      1[39m seqlengths = {[33m"[39m[33mchr1[39m[33m"[39m: [32m100[39m, [33m"[39m[33mchr2[39m[33m"[39m: [32m75[39m, [33m"[39m[33mchr3[39m[33m"[39m: [32m200[39m}
[32m----> [39m[32m3[39m tiles = [43mGenomicRanges[49m[43m.[49m[43mtile_genome[49m[43m([49m[43mseqlengths[49m[43m=[49m[43mseqlengths[49m[43m,[49m[43m [49m[43mn[49m[43m=[49m[32;43m10[39;49m[43m)[49m
[32m      4[39m [38;5;28mprint[39m(tiles)

[31mTypeError[39m: GenomicRanges.tile_genome() got an unexpected keyword argument 'n'

